simple_cross_junior/testcases/IncorrectInputs.txt
Q
O -1
O 10000 &
O 10000 
O 10000 99
O 10000 A123456789
O 10000 IBM F
O 10000 IBM 100
O 10000 IBM BB
O 10000 IBM B 0
O 10000 IBM B 65536
O 10000 IBM B 10 -5
O 10000 IBM B 10 A
O 10000 IBM B 10 100.A
O 10000 IBM B G J
