simple_cross_junior/testcases/SuccessfulCrosses.txt
O 1 SPY B 10 100
O 2 SPY B 10 101
O 3 SPY S 20 99
O 4 SPY B 10 100
O 5 SPY S 5 99
X 4
O 6 SPY B 10 99
O 7 SPY S 10 1

O 8 SPY S 10 1
O 9 SPY B 10 99
O 10 SPY B 10 200
O 11 SPY B 10 100
O 12 SPY S 5 150
O 13 SPY S 15 100
